Workbook

Sheet REGRESSION OUTPUT
A1: SUMMARY OUTPUT
A3: Regression Statistics
A4: Multiple R | B4: 0.77078298
A5: R Square | B5: 0.59410641
A6: Adjusted R Square | B6: 0.15131339
A7: Standard Error | B7: 2473.0707
A8: Observations | B8: 24
A10: ANOVA
B11: df | C11: SS | D11: MS | E11: F | F11: Significance F
A12: Regression | B12: 12 | C12: 98473143 | D12: 8206095.2 | E12: 1.3417249 | F12: 0.31677809
A13: Residual | B13: 11 | C13: 67276867 | D13: 6116078.8
A14: Total | B14: 23 | C14: 165750010
B16: Coefficients | C16: Standard Error | D16: t Stat | E16: P-value | F16: Lower 95% | G16: Upper 95% | H16: Lower 95.0% | I16: Upper 95.0%
A17: Intercept | B17: 26634 | C17: 2313.3458 | D17: 11.513194 | E17: 1.7784585e-07 | F17: 21542.36 | G17: 31725.64 | H17: 21542.36 | I17: 31725.64
A18: T | B18: -40.972222 | C18: 84.135575 | D18: -0.48697857 | E18: 0.63583215 | F18: -226.15337 | G18: 144.20893 | H18: -226.15337 | I18: 144.20893
A19: JAN | B19: -4113.1944 | C19: 2640.5706 | D19: -1.5576915 | E19: 0.14759326 | F19: -9925.0511 | G19: 1698.6622 | H19: -9925.0511 | I19: 1698.6622
A20: FEB | B20: -248.72222 | C20: 2612.2707 | D20: -0.095213034 | E20: 0.92585798 | F20: -5998.2913 | G20: 5500.8469 | H20: -5998.2913 | I20: 5500.8469
A21: MAR | B21: -2679.75 | C21: 2586.3993 | D21: -1.0360929 | E21: 0.32239924 | F21: -8372.3764 | G21: 3012.8764 | H21: -8372.3764 | I21: 3012.8764
A22: APR | B22: 1504.2222 | C22: 2563.0298 | D22: 0.58689221 | E22: 0.56912543 | F22: -4136.9683 | G22: 7145.4128 | H22: -4136.9683 | I22: 7145.4128
A23: MAY | B23: 603.19444 | C23: 2542.2313 | D23: 0.2372697 | E23: 0.81680863 | F23: -4992.2188 | G23: 6198.6077 | H23: -4992.2188 | I23: 6198.6077
A24: JUN | B24: -273.33333 | C24: 2524.0672 | D24: -0.10829083 | E24: 0.91571506 | F24: -5828.7679 | G24: 5282.1012 | H24: -5828.7679 | I24: 5282.1012
A25: JUL | B25: -997.86111 | C25: 2508.595 | D25: -0.39777689 | E25: 0.6984054 | F25: -6519.2414 | G25: 4523.5192 | H25: -6519.2414 | I25: 4523.5192
A26: AUG | B26: 1545.1111 | C26: 2495.8645 | D26: 0.61906851 | E26: 0.54847771 | F26: -3948.2496 | G26: 7038.4718 | H26: -3948.2496 | I26: 7038.4718
A27: SEP | B27: -3631.4167 | C27: 2485.9179 | D27: -1.4607951 | E27: 0.17203897 | F27: -9102.8852 | G27: 1840.0518 | H27: -9102.8852 | I27: 1840.0518
A28: OCT | B28: -3181.4444 | C28: 2478.7888 | D28: -1.2834673 | E28: 0.22570738 | F28: -8637.2219 | G28: 2274.333 | H28: -8637.2219 | I28: 2274.333
A29: NOV | B29: -3638.9722 | C29: 2474.5015 | D29: -1.470588 | E29: 0.1694199 | F29: -9085.3133 | G29: 1807.3688 | H29: -9085.3133 | I29: 1807.3688
A33: RESIDUAL OUTPUT
A35: Observation | B35: Predicted SALES | C35: Residuals
A36: 1 | B36: 22479.833 | C36: -1909.8333
A37: 2 | B37: 26303.333 | C37: 2450.6667
A38: 3 | B38: 23831.333 | C38: 495.66667
A39: 4 | B39: 27974.333 | C39: -1938.3333
A40: 5 | B40: 27032.333 | C40: -2456.3333
A41: 6 | B41: 26114.833 | C41: 52.166667
A42: 7 | B42: 25349.333 | C42: 2256.6667
A43: 8 | B43: 27851.333 | C43: 1879.6667
A44: 9 | B44: 22633.833 | C44: 833.16667
A45: 10 | B45: 23042.833 | C45: -300.83333
A46: 11 | B46: 22544.333 | C46: -2024.3333
A47: 12 | B47: 26142.333 | C47: 661.66667
...

Sheet DATA
A1: PERIOD | B1: MONTH | C1: SALES | D1: FORECASTED SALES | E1: T | F1: JAN | G1: FEB | H1: MAR | I1: APR | J1: MAY | K1: JUN | L1: JUL | M1: AUG | N1: SEP | O1: OCT | P1: NOV | R1: Predicted SALES | S1: Residuals
A2: 45292 | B2: JAN | C2: 20570 | D2: =+'REGRESSION OUTPUT'!$B$17+MMULT(DATA!E2:P2,'REGRESSION OUTPUT'!$B$18:$B$29) -> 22479.833 | E2: 1 | F2: =IF($B2=F$1,1,0) -> 1 | G2: =IF($B2=G$1,1,0) -> 0 | H2: =IF($B2=H$1,1,0) -> 0 | I2: =IF($B2=I$1,1,0) -> 0 | J2: =IF($B2=J$1,1,0) -> 0 | K2: =IF($B2=K$1,1,0) -> 0 | L2: =IF($B2=L$1,1,0) -> 0 | M2: =IF($B2=M$1,1,0) -> 0 | ... P2: =IF($B2=P$1,1,0) -> 0 | R2: 22479.833 | S2: -1909.8333
A3: 45323 | B3: FEB | C3: 28754 | D3: =+'REGRESSION OUTPUT'!$B$17+MMULT(DATA!E3:P3,'REGRESSION OUTPUT'!$B$18:$B$29) -> 26303.333 | E3: 2 | F3: =IF($B3=F$1,1,0) -> 0 | G3: =IF($B3=G$1,1,0) -> 1 | H3: =IF($B3=H$1,1,0) -> 0 | I3: =IF($B3=I$1,1,0) -> 0 | J3: =IF($B3=J$1,1,0) -> 0 | K3: =IF($B3=K$1,1,0) -> 0 | L3: =IF($B3=L$1,1,0) -> 0 | M3: =IF($B3=M$1,1,0) -> 0 | ... P3: =IF($B3=P$1,1,0) -> 0 | R3: 26303.333 | S3: 2450.6667
A4: 45352 | B4: MAR | C4: 24327 | D4: =+'REGRESSION OUTPUT'!$B$17+MMULT(DATA!E4:P4,'REGRESSION OUTPUT'!$B$18:$B$29) -> 23831.333 | E4: 3 | F4: =IF($B4=F$1,1,0) -> 0 | G4: =IF($B4=G$1,1,0) -> 0 | H4: =IF($B4=H$1,1,0) -> 1 | I4: =IF($B4=I$1,1,0) -> 0 | J4: =IF($B4=J$1,1,0) -> 0 | K4: =IF($B4=K$1,1,0) -> 0 | L4: =IF($B4=L$1,1,0) -> 0 | M4: =IF($B4=M$1,1,0) -> 0 | ... P4: =IF($B4=P$1,1,0) -> 0 | R4: 23831.333 | S4: 495.66667
A5: 45383 | B5: APR | C5: 26036 | D5: =+'REGRESSION OUTPUT'!$B$17+MMULT(DATA!E5:P5,'REGRESSION OUTPUT'!$B$18:$B$29) -> 27974.333 | E5: 4 | F5: =IF($B5=F$1,1,0) -> 0 | G5: =IF($B5=G$1,1,0) -> 0 | H5: =IF($B5=H$1,1,0) -> 0 | I5: =IF($B5=I$1,1,0) -> 1 | J5: =IF($B5=J$1,1,0) -> 0 | K5: =IF($B5=K$1,1,0) -> 0 | L5: =IF($B5=L$1,1,0) -> 0 | M5: =IF($B5=M$1,1,0) -> 0 | ... P5: =IF($B5=P$1,1,0) -> 0 | R5: 27974.333 | S5: -1938.3333
A6: 45413 | B6: MAY | C6: 24576 | D6: =+'REGRESSION OUTPUT'!$B$17+MMULT(DATA!E6:P6,'REGRESSION OUTPUT'!$B$18:$B$29) -> 27032.333 | E6: 5 | F6: =IF($B6=F$1,1,0) -> 0 | G6: =IF($B6=G$1,1,0) -> 0 | H6: =IF($B6=H$1,1,0) -> 0 | I6: =IF($B6=I$1,1,0) -> 0 | J6: =IF($B6=J$1,1,0) -> 1 | K6: =IF($B6=K$1,1,0) -> 0 | L6: =IF($B6=L$1,1,0) -> 0 | M6: =IF($B6=M$1,1,0) -> 0 | ... P6: =IF($B6=P$1,1,0) -> 0 | R6: 27032.333 | S6: -2456.3333
A7: 45444 | B7: JUN | C7: 26167 | D7: =+'REGRESSION OUTPUT'!$B$17+MMULT(DATA!E7:P7,'REGRESSION OUTPUT'!$B$18:$B$29) -> 26114.833 | E7: 6 | F7: =IF($B7=F$1,1,0) -> 0 | G7: =IF($B7=G$1,1,0) -> 0 | H7: =IF($B7=H$1,1,0) -> 0 | I7: =IF($B7=I$1,1,0) -> 0 | J7: =IF($B7=J$1,1,0) -> 0 | K7: =IF($B7=K$1,1,0) -> 1 | L7: =IF($B7=L$1,1,0) -> 0 | M7: =IF($B7=M$1,1,0) -> 0 | ... P7: =IF($B7=P$1,1,0) -> 0 | R7: 26114.833 | S7: 52.166667
A8: 45474 | B8: JUL | C8: 27606 | D8: =+'REGRESSION OUTPUT'!$B$17+MMULT(DATA!E8:P8,'REGRESSION OUTPUT'!$B$18:$B$29) -> 25349.333 | E8: 7 | F8: =IF($B8=F$1,1,0) -> 0 | G8: =IF($B8=G$1,1,0) -> 0 | H8: =IF($B8=H$1,1,0) -> 0 | I8: =IF($B8=I$1,1,0) -> 0 | J8: =IF($B8=J$1,1,0) -> 0 | K8: =IF($B8=K$1,1,0) -> 0 | L8: =IF($B8=L$1,1,0) -> 1 | M8: =IF($B8=M$1,1,0) -> 0 | ... P8: =IF($B8=P$1,1,0) -> 0 | R8: 25349.333 | S8: 2256.6667
A9: 45505 | B9: AUG | C9: 29731 | D9: =+'REGRESSION OUTPUT'!$B$17+MMULT(DATA!E9:P9,'REGRESSION OUTPUT'!$B$18:$B$29) -> 27851.333 | E9: 8 | F9: =IF($B9=F$1,1,0) -> 0 | G9: =IF($B9=G$1,1,0) -> 0 | H9: =IF($B9=H$1,1,0) -> 0 | I9: =IF($B9=I$1,1,0) -> 0 | J9: =IF($B9=J$1,1,0) -> 0 | K9: =IF($B9=K$1,1,0) -> 0 | L9: =IF($B9=L$1,1,0) -> 0 | M9: =IF($B9=M$1,1,0) -> 1 | ... P9: =IF($B9=P$1,1,0) -> 0 | R9: 27851.333 | S9: 1879.6667
A10: 45536 | B10: SEP | C10: 23467 | D10: =+'REGRESSION OUTPUT'!$B$17+MMULT(DATA!E10:P10,'REGRESSION OUTPUT'!$B$18:$B$29) -> 22633.833 | E10: 9 | F10: =IF($B10=F$1,1,0) -> 0 | G10: =IF($B10=G$1,1,0) -> 0 | H10: =IF($B10=H$1,1,0) -> 0 | I10: =IF($B10=I$1,1,0) -> 0 | J10: =IF($B10=J$1,1,0) -> 0 | K10: =IF($B10=K$1,1,0) -> 0 | L10: =IF($B10=L$1,1,0) -> 0 | M10: =IF($B10=M$1,1,0) -> 0 | ... P10: =IF($B10=P$1,1,0) -> 0 | R10: 22633.833 | S10: 833.16667
A11: 45566 | B11: OCT | C11: 22742 | D11: =+'REGRESSION OUTPUT'!$B$17+MMULT(DATA!E11:P11,'REGRESSION OUTPUT'!$B$18:$B$29) -> 23042.833 | E11: 10 | F11: =IF($B11=F$1,1,0) -> 0 | G11: =IF($B11=G$1,1,0) -> 0 | H11: =IF($B11=H$1,1,0) -> 0 | I11: =IF($B11=I$1,1,0) -> 0 | J11: =IF($B11=J$1,1,0) -> 0 | K11: =IF($B11=K$1,1,0) -> 0 | L11: =IF($B11=L$1,1,0) -> 0 | M11: =IF($B11=M$1,1,0) -> 0 | ... P11: =IF($B11=P$1,1,0) -> 0 | R11: 23042.833 | S11: -300.83333
A12: 45597 | B12: NOV | C12: 20520 | D12: =+'REGRESSION OUTPUT'!$B$17+MMULT(DATA!E12:P12,'REGRESSION OUTPUT'!$B$18:$B$29) -> 22544.333 | E12: 11 | F12: =IF($B12=F$1,1,0) -> 0 | G12: =IF($B12=G$1,1,0) -> 0 | H12: =IF($B12=H$1,1,0) -> 0 | I12: =IF($B12=I$1,1,0) -> 0 | J12: =IF($B12=J$1,1,0) -> 0 | K12: =IF($B12=K$1,1,0) -> 0 | L12: =IF($B12=L$1,1,0) -> 0 | M12: =IF($B12=M$1,1,0) -> 0 | ... P12: =IF($B12=P$1,1,0) -> 1 | R12: 22544.333 | S12: -2024.3333
A13: 45627 | B13: DEC | C13: 26804 | D13: =+'REGRESSION OUTPUT'!$B$17+MMULT(DATA!E13:P13,'REGRESSION OUTPUT'!$B$18:$B$29) -> 26142.333 | E13: 12 | F13: =IF($B13=F$1,1,0) -> 0 | G13: =IF($B13=G$1,1,0) -> 0 | H13: =IF($B13=H$1,1,0) -> 0 | I13: =IF($B13=I$1,1,0) -> 0 | J13: =IF($B13=J$1,1,0) -> 0 | K13: =IF($B13=K$1,1,0) -> 0 | L13: =IF($B13=L$1,1,0) -> 0 | M13: =IF($B13=M$1,1,0) -> 0 | ... P13: =IF($B13=P$1,1,0) -> 0 | R13: 26142.333 | S13: 661.66667
... A25: 45992 | B25: DEC | C25: 24989 | D25: =+'REGRESSION OUTPUT'!$B$17+MMULT(DATA!E25:P25,'REGRESSION OUTPUT'!$B$18:$B$29) -> 25650.667 | E25: 24 | F25: =IF($B25=F$1,1,0) -> 0 | G25: =IF($B25=G$1,1,0) -> 0 | H25: =IF($B25=H$1,1,0) -> 0 | I25: =IF($B25=I$1,1,0) -> 0 | J25: =IF($B25=J$1,1,0) -> 0 | K25: =IF($B25=K$1,1,0) -> 0 | L25: =IF($B25=L$1,1,0) -> 0 | M25: =IF($B25=M$1,1,0) -> 0 | ... P25: =IF($B25=P$1,1,0) -> 0 | R25: 25650.667 | S25: -661.66667
A26: 46023 | B26: JAN | D26: =+'REGRESSION OUTPUT'!$B$17+MMULT(DATA!E26:P26,'REGRESSION OUTPUT'!$B$18:$B$29) -> 21496.5 | E26: 25 | F26: =IF($B26=F$1,1,0) -> 1 | G26: =IF($B26=G$1,1,0) -> 0 | H26: =IF($B26=H$1,1,0) -> 0 | I26: =IF($B26=I$1,1,0) -> 0 | J26: =IF($B26=J$1,1,0) -> 0 | K26: =IF($B26=K$1,1,0) -> 0 | L26: =IF($B26=L$1,1,0) -> 0 | M26: =IF($B26=M$1,1,0) -> 0 | ... P26: =IF($B26=P$1,1,0) -> 0
A27: 46054 | B27: FEB | D27: =+'REGRESSION OUTPUT'!$B$17+MMULT(DATA!E27:P27,'REGRESSION OUTPUT'!$B$18:$B$29) -> 25320 | E27: 26 | F27: =IF($B27=F$1,1,0) -> 0 | G27: =IF($B27=G$1,1,0) -> 1 | H27: =IF($B27=H$1,1,0) -> 0 | I27: =IF($B27=I$1,1,0) -> 0 | J27: =IF($B27=J$1,1,0) -> 0 | K27: =IF($B27=K$1,1,0) -> 0 | L27: =IF($B27=L$1,1,0) -> 0 | M27: =IF($B27=M$1,1,0) -> 0 | ... P27: =IF($B27=P$1,1,0) -> 0
A28: 46082 | B28: MAR | D28: =+'REGRESSION OUTPUT'!$B$17+MMULT(DATA!E28:P28,'REGRESSION OUTPUT'!$B$18:$B$29) -> 22848 | E28: 27 | F28: =IF($B28=F$1,1,0) -> 0 | G28: =IF($B28=G$1,1,0) -> 0 | H28: =IF($B28=H$1,1,0) -> 1 | I28: =IF($B28=I$1,1,0) -> 0 | J28: =IF($B28=J$1,1,0) -> 0 | K28: =IF($B28=K$1,1,0) -> 0 | L28: =IF($B28=L$1,1,0) -> 0 | M28: =IF($B28=M$1,1,0) -> 0 | ... P28: =IF($B28=P$1,1,0) -> 0
A29: 46113 | B29: APR | D29: =+'REGRESSION OUTPUT'!$B$17+MMULT(DATA!E29:P29,'REGRESSION OUTPUT'!$B$18:$B$29) -> 26991 | E29: 28 | F29: =IF($B29=F$1,1,0) -> 0 | G29: =IF($B29=G$1,1,0) -> 0 | H29: =IF($B29=H$1,1,0) -> 0 | I29: =IF($B29=I$1,1,0) -> 1 | J29: =IF($B29=J$1,1,0) -> 0 | K29: =IF($B29=K$1,1,0) -> 0 | L29: =IF($B29=L$1,1,0) -> 0 | M29: =IF($B29=M$1,1,0) -> 0 | ... P29: =IF($B29=P$1,1,0) -> 0
A30: 46143 | B30: MAY | D30: =+'REGRESSION OUTPUT'!$B$17+MMULT(DATA!E30:P30,'REGRESSION OUTPUT'!$B$18:$B$29) -> 26049 | E30: 29 | F30: =IF($B30=F$1,1,0) -> 0 | G30: =IF($B30=G$1,1,0) -> 0 | H30: =IF($B30=H$1,1,0) -> 0 | I30: =IF($B30=I$1,1,0) -> 0 | J30: =IF($B30=J$1,1,0) -> 1 | K30: =IF($B30=K$1,1,0) -> 0 | L30: =IF($B30=L$1,1,0) -> 0 | M30: =IF($B30=M$1,1,0) -> 0 | ... P30: =IF($B30=P$1,1,0) -> 0
A31: 46174 | B31: JUN | D31: =+'REGRESSION OUTPUT'!$B$17+MMULT(DATA!E31:P31,'REGRESSION OUTPUT'!$B$18:$B$29) -> 25131.5 | E31: 30 | F31: =IF($B31=F$1,1,0) -> 0 | G31: =IF($B31=G$1,1,0) -> 0 | H31: =IF($B31=H$1,1,0) -> 0 | I31: =IF($B31=I$1,1,0) -> 0 | J31: =IF($B31=J$1,1,0) -> 0 | K31: =IF($B31=K$1,1,0) -> 1 | L31: =IF($B31=L$1,1,0) -> 0 | M31: =IF($B31=M$1,1,0) -> 0 | ... P31: =IF($B31=P$1,1,0) -> 0
A32: 46204 | B32: JUL | D32: =+'REGRESSION OUTPUT'!$B$17+MMULT(DATA!E32:P32,'REGRESSION OUTPUT'!$B$18:$B$29) -> 24366 | E32: 31 | F32: =IF($B32=F$1,1,0) -> 0 | G32: =IF($B32=G$1,1,0) -> 0 | H32: =IF($B32=H$1,1,0) -> 0 | I32: =IF($B32=I$1,1,0) -> 0 | J32: =IF($B32=J$1,1,0) -> 0 | K32: =IF($B32=K$1,1,0) -> 0 | L32: =IF($B32=L$1,1,0) -> 1 | M32: =IF($B32=M$1,1,0) -> 0 | ... P32: =IF($B32=P$1,1,0) -> 0
A33: 46235 | B33: AUG | D33: =+'REGRESSION OUTPUT'!$B$17+MMULT(DATA!E33:P33,'REGRESSION OUTPUT'!$B$18:$B$29) -> 26868 | E33: 32 | F33: =IF($B33=F$1,1,0) -> 0 | G33: =IF($B33=G$1,1,0) -> 0 | H33: =IF($B33=H$1,1,0) -> 0 | I33: =IF($B33=I$1,1,0) -> 0 | J33: =IF($B33=J$1,1,0) -> 0 | K33: =IF($B33=K$1,1,0) -> 0 | L33: =IF($B33=L$1,1,0) -> 0 | M33: =IF($B33=M$1,1,0) -> 1 | ... P33: =IF($B33=P$1,1,0) -> 0
A34: 46266 | B34: SEP | D34: =+'REGRESSION OUTPUT'!$B$17+MMULT(DATA!E34:P34,'REGRESSION OUTPUT'!$B$18:$B$29) -> 21650.5 | E34: 33 | F34: =IF($B34=F$1,1,0) -> 0 | G34: =IF($B34=G$1,1,0) -> 0 | H34: =IF($B34=H$1,1,0) -> 0 | I34: =IF($B34=I$1,1,0) -> 0 | J34: =IF($B34=J$1,1,0) -> 0 | K34: =IF($B34=K$1,1,0) -> 0 | L34: =IF($B34=L$1,1,0) -> 0 | M34: =IF($B34=M$1,1,0) -> 0 | ... P34: =IF($B34=P$1,1,0) -> 0
A35: 46296 | B35: OCT | D35: =+'REGRESSION OUTPUT'!$B$17+MMULT(DATA!E35:P35,'REGRESSION OUTPUT'!$B$18:$B$29) -> 22059.5 | E35: 34 | F35: =IF($B35=F$1,1,0) -> 0 | G35: =IF($B35=G$1,1,0) -> 0 | H35: =IF($B35=H$1,1,0) -> 0 | I35: =IF($B35=I$1,1,0) -> 0 | J35: =IF($B35=J$1,1,0) -> 0 | K35: =IF($B35=K$1,1,0) -> 0 | L35: =IF($B35=L$1,1,0) -> 0 | M35: =IF($B35=M$1,1,0) -> 0 | ... P35: =IF($B35=P$1,1,0) -> 0
A36: 46327 | B36: NOV | D36: =+'REGRESSION OUTPUT'!$B$17+MMULT(DATA!E36:P36,'REGRESSION OUTPUT'!$B$18:$B$29) -> 21561 | E36: 35 | F36: =IF($B36=F$1,1,0) -> 0 | G36: =IF($B36=G$1,1,0) -> 0 | H36: =IF($B36=H$1,1,0) -> 0 | I36: =IF($B36=I$1,1,0) -> 0 | J36: =IF($B36=J$1,1,0) -> 0 | K36: =IF($B36=K$1,1,0) -> 0 | L36: =IF($B36=L$1,1,0) -> 0 | M36: =IF($B36=M$1,1,0) -> 0 | ... P36: =IF($B36=P$1,1,0) -> 1
A37: 46357 | B37: DEC | D37: =+'REGRESSION OUTPUT'!$B$17+MMULT(DATA!E37:P37,'REGRESSION OUTPUT'!$B$18:$B$29) -> 25159 | E37: 36 | F37: =IF($B37=F$1,1,0) -> 0 | G37: =IF($B37=G$1,1,0) -> 0 | H37: =IF($B37=H$1,1,0) -> 0 | I37: =IF($B37=I$1,1,0) -> 0 | J37: =IF($B37=J$1,1,0) -> 0 | K37: =IF($B37=K$1,1,0) -> 0 | L37: =IF($B37=L$1,1,0) -> 0 | M37: =IF($B37=M$1,1,0) -> 0 | ... P37: =IF($B37=P$1,1,0) -> 0

Sheet GRAPH
